<?xml version='1.0'?>

<robot name="mybot" xmlns:xacro="http://www.ros.org/wiki/xacro">

  <xacro:property name="cameraHeight" value="0.025"/>
  <xacro:property name="cameraLength" value="0.025"/>
  <xacro:property name="cameraWidth" value="0.09"/>
  <xacro:property name="cameraMass" value="0.1"/>

  <xacro:include filename="$(find mybot_description)/urdf/mybot.gazebo" />
  <xacro:include filename="$(find mybot_description)/urdf/materials.xacro" />
  <xacro:include filename="$(find mybot_description)/urdf/macros.xacro" />


  <link name='chassis'>
    <pose>0 0 0.1 0 0 0</pose>
    <!--
    <inertial>
      <mass value="10.0"/>
      <origin xyz="0.0 0 0.08" rpy=" 0 0 0"/>
      <inertia
          ixx="0.5" ixy="0" ixz="0"
          iyy="1.0" iyz="0"
          izz="0.1"
      />
    </inertial>
    -->
    <collision name='collision'>
      <geometry>
        <cylinder radius="0.2" length="0.05"/> <!--box size=".4 .2 .1"/>-->
      </geometry>
    </collision>

    <visual name='chassis_visual'>
      <origin xyz="0 0 0" rpy=" 0 0 0"/>
      <geometry>
        <cylinder radius="0.2" length="0.05"/> <!--box size=".4 .2 .1"/>-->
      </geometry>
      <material name="orange" />
    </visual>


    <collision name='front_caster_collision'>
      <origin xyz="0.17 0 -0.04" rpy=" 0 0 0"/>
      <geometry>
        <sphere radius="0.04"/>
      </geometry>
      <surface>
        <friction>
          <ode>
            <mu>0</mu>
            <mu2>0</mu2>
            <slip1>1.0</slip1>
            <slip2>1.0</slip2>
          </ode>
        </friction>
      </surface>
    </collision>
    <visual name='front_caster_visual'>
      <origin xyz="0.17 0 -0.04" rpy=" 0 0 0"/>
      <geometry>
        <sphere radius="0.04"/>
      </geometry>
    </visual>
  
    <collision name='rear_caster_collision'>
      <origin xyz="-0.17 0 -0.04" rpy=" 0 0 0"/>
      <geometry>
        <sphere radius="0.04"/>
      </geometry>
      <surface>
        <friction>
          <ode>
            <mu>0</mu>
            <mu2>0</mu2>
            <slip1>1.0</slip1>
            <slip2>1.0</slip2>
          </ode>
        </friction>
      </surface>
    </collision>
    <visual name='rear_caster_visual'>
      <origin xyz="-0.17 0 -0.04" rpy=" 0 0 0"/>
      <geometry>
        <sphere radius="0.04"/>
      </geometry>
    </visual>
  </link>



  <link name="left_wheel">
    <!--origin xyz="0.1 0.13 0.1" rpy="0 1.5707 1.5707"/-->
    <collision name="collision">
      <origin xyz="0 0 0" rpy="0 1.5707 1.5707"/>
      <geometry>
        <cylinder radius="0.08" length="0.03"/>
      </geometry>
    </collision>
    <visual name="left_wheel_visual">
      <origin xyz="0 0 0" rpy="0 1.5707 1.5707"/>
      <geometry>
        <cylinder radius="0.08" length="0.03"/>
      </geometry>
    </visual>
    <inertial>
      <origin xyz="0 0 0" rpy="0 1.5707 1.5707"/>
      <mass value="5"/>
      <cylinder_inertia m="5" r="0.08" h="0.04"/>
      <inertia
        ixx="1.0" ixy="0.0" ixz="0.0"
        iyy="1.0" iyz="0.0"
        izz="1.0"/>
    </inertial>
  </link>

  <link name="right_wheel">
    <!--origin xyz="0.1 -0.13 0.1" rpy="0 1.5707 1.5707"/-->
    <collision name="collision">
      <origin xyz="0 0 0" rpy="0 1.5707 1.5707"/>
      <geometry>
        <cylinder radius="0.08" length="0.03"/>
      </geometry>
    </collision>
    <visual name="right_wheel_visual">
      <origin xyz="0 0 0" rpy="0 1.5707 1.5707"/>
      <geometry>
        <cylinder radius="0.08" length="0.03"/>
      </geometry>
    </visual>
    <inertial>
      <origin xyz="0 0 0" rpy="0 1.5707 1.5707"/>
      <mass value="5"/>
      <cylinder_inertia m="5" r="0.08" h="0.04"/>
      <inertia
        ixx="1.0" ixy="0.0" ixz="0.0"
        iyy="1.0" iyz="0.0"
        izz="1.0"/>
    </inertial>
  </link>


  <joint type="continuous" name="left_wheel_hinge">
    <origin xyz="0.0 0.2 0" rpy="0 0 0"/>
    <child link="left_wheel"/>
    <parent link="chassis"/>
    <axis xyz="0 1 0" rpy="0 0 0"/>
    <limit effort="100" velocity="100"/>
    <joint_properties damping="0.0" friction="0.01"/>
  </joint>

  <joint type="continuous" name="right_wheel_hinge">
    <origin xyz="0.0 -0.2 0" rpy="0 0 0"/>
    <child link="right_wheel"/>
    <parent link="chassis"/>
    <axis xyz="0 1 0" rpy="0 0 0"/>
    <limit effort="100" velocity="100"/>
    <joint_properties damping="0.0" friction="0.01"/>
  </joint>


  <link name="camera">
    <collision>
      <origin xyz="0 0 0" rpy="0 0 0"/>
      <geometry>
        <box size="${cameraLength} ${cameraWidth} ${cameraHeight}"/>
      </geometry>
    </collision>

    <visual>
      <origin xyz="0 0 0" rpy="0 0 0"/>
      <geometry>
        <box size="${cameraLength} ${cameraWidth} ${cameraHeight}"/>
      </geometry>
      <material name="green"/>
    </visual>

    <inertial>
      <mass value="${cameraMass}" />
      <origin xyz="0 0 0" rpy="0 0 0"/>
      <box_inertia m="${cameraMass}" x="${cameraLength}" y="${cameraWidth}" z="${cameraHeight}" />
      <inertia ixx="1e-6" ixy="0" ixz="0" iyy="1e-6" iyz="0" izz="1e-6" />
    </inertial>
  </link>

  <joint name="camera_joint" type="fixed">
    <axis xyz="0 1 0" />
    <origin xyz=".18 0 0.025" rpy="0 0 0"/>
    <parent link="chassis"/>
    <child link="camera"/>
  </joint>


  <!-- rplidar Laser -->
  <link name="laser">
    <collision>
      <origin xyz="0 0 0" rpy="1.5707 0 4.71"/>
      <geometry>
        <mesh filename="package://mybot_description/meshes/rplidar.dae" scale="0.001 0.001 0.001" />
      </geometry>
    </collision>

    <visual>
      <origin xyz="0 0 0" rpy="1.5707 0 4.71"/>
      <geometry>
        <mesh filename="package://mybot_description/meshes/rplidar.dae" scale="0.001 0.001 0.001" />
      </geometry>
    </visual>

    <inertial>
      <mass value="1e-5" />
      <origin xyz="0 0 0" rpy="1.5707 0 4.71"/>
      <inertia ixx="0" ixy="0" ixz="0" iyy="0" iyz="0" izz="0" />
    </inertial>
  </link>

  <joint name="range_fl_joint" type="fixed">
    <axis xyz="0 1 0" />
    <origin xyz="0.1 0.05 0.01" rpy="0 0 0.13 "/>
    <parent link="chassis"/>
    <child link="range_fl"/>
  </joint>
  <link name="range_fl"></link>

  <joint name="range_fr_joint" type="fixed">
    <axis xyz="0 1 0" />
    <origin xyz="0.1 -0.05 0.01" rpy="0 0 -0.13 "/>
    <parent link="chassis"/>
    <child link="range_fr"/>
  </joint>
  <link name="range_fr"></link>

  <joint name="range_rl_joint" type="fixed">
    <axis xyz="0 1 0" />
    <origin xyz="-0.1 0.05 0.01" rpy="0 0 3.01 "/>
    <parent link="chassis"/>
    <child link="range_rl"/>
  </joint>
  <link name="range_rl"></link>

  <joint name="range_rr_joint" type="fixed">
    <axis xyz="0 1 0" />
    <origin xyz="-0.1 -0.05 0.01" rpy="0 0 3.27 "/>
    <parent link="chassis"/>
    <child link="range_rr"/>
  </joint>
  <link name="range_rr"></link>
  
  <joint name="rplidar_joint" type="fixed">
    <axis xyz="0 1 0" />
    <origin xyz="0 0 0.1" rpy="0 0 3.14"/>
    <parent link="chassis"/>
    <child link="laser"/>
  </joint>

</robot>
